Workbook

Sheet CDI
B1: Nom | C1: Prénom | D1: Date entrée | E1: Emploi | F1: SALAIRE CONTRACTUEL 11/2022 | G1: Charges Patronales | H1: Taux de charges | I1: SALAIRES BRUTS 2023 RETENUS | J1: Cotisations sociales | N1: Nbre TR | O1: MONTANT | P1: Taxe sur les salaires taux global | Q1: Taux Majo 1er tranche | R1: Taux majo 2e Tranche | S1: Total T.S.
N2: =20*10.5 -> 210 | O2: =N2*5.5 -> 1155 | P2: =I2*0.0425 -> 0 | Q2: =IF(I2>16013,(I2-8020)*0.0425,0) -> 0 | R2: =IF(I2>16013,(I2-16013)*0.051,0) -> 0 | S2: =SUM(P2:R2) -> 0
B3: BRACQ | C3: JEAN JACQUES | D3: 01/09/1996 | E3: FORMATEUR RESP. SECTEUR | F3: 3410.5 | G3: =1861.56-111-207.25-28.69-151.71-0.55-34.11 -> 1328.25 | H3: =G3/F3 -> 0.38945902 | I3: =F3*12 -> 40926 | J3: =H3*I3 -> 15939 | N3: =20*10.5 -> 210 | O3: =N3*5.5 -> 1155 | P3: =I3*0.0425 -> 1739.355 | Q3: =IF(I3>16013,(I3-8020)*0.0425,0) -> 1398.505 | R3: =IF(I3>16013,(I3-16013)*0.051,0) -> 1270.563 | S3: =SUM(P3:R3) -> 4408.423
B4: BRUXELLE | C4: JOEL | D4: 21/02/2022 | E4: FORMATEUR | F4: 2834.44 | G4: =1518.81-111-148.99-28.69-125.23-0.45-28.34 -> 1076.11 | H4: =G4/F4 -> 0.37965524 | I4: =F4*12 -> 34013.28 | J4: =H4*I4 -> 12913.32 | N4: =20*10.5 -> 210 | O4: =N4*5.5 -> 1155 | P4: =I4*0.0425 -> 1445.5644 | Q4: =IF(I4>16013,(I4-8020)*0.0425,0) -> 1104.7144 | R4: =IF(I4>16013,(I4-16013)*0.051,0) -> 918.01428 | S4: =SUM(P4:R4) -> 3468.2931
B5: CHRETIEN | C5: CASSANDRA | D5: 01/02/2021 | E5: AIDE DOCUMENTALISTE | F5: 1707.54 | G5: =766.31-111-60.45-28.69-84.98-0.31-18.65 -> 462.23 | H5: =G5/F5 -> 0.27069937 | I5: =F5*12 -> 20490.48 | J5: =H5*I5 -> 5546.76 | N5: =20*10.5 -> 210 | O5: =N5*5.5 -> 1155 | P5: =I5*0.0425 -> 870.8454 | Q5: =IF(I5>16013,(I5-8020)*0.0425,0) -> 529.9954 | R5: =IF(I5>16013,(I5-16013)*0.051,0) -> 228.35148 | S5: =SUM(P5:R5) -> 1629.1923
B6: CORMONT | C6: OLIVIER | D6: 01/11/2000 | E6: Resp. Centre Ressources | F6: 3080.45 | G6: =1893.16-111-212.62-28.69-154.15-0.55-34.62 -> 1351.53 | H6: =G6/F6 -> 0.43874434 | I6: =F6*12 -> 36965.4 | J6: =H6*I6 -> 16218.36 | N6: =20*10.5 -> 210 | O6: =N6*5.5 -> 1155 | P6: =I6*0.0425 -> 1571.0295 | Q6: =IF(I6>16013,(I6-8020)*0.0425,0) -> 1230.1795 | R6: =IF(I6>16013,(I6-16013)*0.051,0) -> 1068.5724 | S6: =SUM(P6:R6) -> 3869.7814
B7: CSIZMADIA | C7: CELINE | D7: 02/05/2022 | E7: FORMATRICE | F7: 2750.4 | G7: =1505.06-111-143.2-28.69-122.59-0.44-27.5-7.71 -> 1063.93 | H7: =G7/F7 -> 0.38682737 | I7: =F7*12 -> 33004.8 | J7: =H7*I7 -> 12767.16 | N7: =20*10.5 -> 210 | O7: =N7*5.5 -> 1155 | P7: =I7*0.0425 -> 1402.704 | Q7: =IF(I7>16013,(I7-8020)*0.0425,0) -> 1061.854 | R7: =IF(I7>16013,(I7-16013)*0.051,0) -> 866.5818 | S7: =SUM(P7:R7) -> 3331.1398
B8: DEFACQUES | C8: EMILIE | D8: 45108 | E8: FORMATRICE | F8: 2914.49 | G8: 1295.86 | H8: =G8/F8 -> 0.44462668 | I8: =F8*12 -> 34973.88 | J8: =H8*I8 -> 15550.32 | P8: =I8*0.0425 -> 1486.3899 | Q8: =IF(I8>16013,(I8-8020)*0.0425,0) -> 1145.5399 | R8: =IF(I8>16013,(I8-16013)*0.051,0) -> 967.00488 | S8: =SUM(P8:R8) -> 3598.9347
B9: DECOOL | C9: ELODIE | D9: 01/01/2018 | E9: SECRETAIRE ADMINISTRATIVE | F9: 1841.24 | G9: =1333.68-111-144.04-28.69-122.98-0.43 -> 926.54 | H9: 0.27 | I9: =F9*12 -> 22094.88 | J9: =H9*I9 -> 5965.6176 | N9: =20*10.5 -> 210 | O9: =N9*5.5 -> 1155 | P9: =I9*0.0425 -> 939.0324 | Q9: =IF(I9>16013,(I9-8020)*0.0425,0) -> 598.1824 | R9: =IF(I9>16013,(I9-16013)*0.051,0) -> 310.17588 | S9: =SUM(P9:R9) -> 1847.3907
B10: DELABIE | C10: CHARLOTTE | D10: 01/09/2021 | E10: DIRECTEUR | F10: 3247 | G10: =1981.5-111-233.65-28.69-163.71-0.59-37.05 -> 1406.81 | H10: =G10/F10 -> 0.43326455 | I10: =F10*12 -> 38964 | J10: =H10*I10 -> 16881.72 | N10: =20*10.5 -> 210 | O10: =N10*5.5 -> 1155 | P10: =I10*0.0425 -> 1655.97 | Q10: =IF(I10>16013,(I10-8020)*0.0425,0) -> 1315.12 | R10: =IF(I10>16013,(I10-16013)*0.051,0) -> 1170.501 | S10: =SUM(P10:R10) -> 4141.591
B11: DUGUE | C11: PIERRE | D11: 01/09/2015 | E11: responsable site Avion | F11: 3162.96 | G11: =2059.7-111-240.88-28.69-167-0.6-37.36 -> 1474.17 | H11: =G11/F11 -> 0.46607292 | I11: =F11*12 -> 37955.52 | J11: =H11*I11 -> 17690.04 | N11: =20*10.5 -> 210 | O11: =N11*5.5 -> 1155 | P11: =I11*0.0425 -> 1613.1096 | Q11: =IF(I11>16013,(I11-8020)*0.0425,0) -> 1272.2596 | R11: =IF(I11>16013,(I11-16013)*0.051,0) -> 1119.0685 | S11: =SUM(P11:R11) -> 4004.4377
B12: EVRARD | C12: OLIVIER | D12: 01/10/2022 | E12: FORMATEUR | F12: 2829.6 | G12: 1547.56 | H12: =G12/F12 -> 0.54691829 | I12: =F12*12 -> 33955.2 | J12: =H12*I12 -> 18570.72 | N12: =20*10.5 -> 210 | O12: =N12*5.5 -> 1155 | P12: =I12*0.0425 -> 1443.096 | Q12: =IF(I12>16013,(I12-8020)*0.0425,0) -> 1102.246 | R12: =IF(I12>16013,(I12-16013)*0.051,0) -> 915.0522 | S12: =SUM(P12:R12) -> 3460.3942
B13: EYZOP | C13: BENEDICTE | D13: 15/10/2012 | E13: AGENT ADMINISTRATIF | F13: 1959.66 | G13: =1467.02-55.5-161.29-28.69-130.81-0.46-28.84 -> 1061.43 | H13: 0.27 | I13: =F13*12 -> 23515.92 | J13: =H13*I13 -> 6349.2984 | N13: =20*10.5 -> 210 | O13: =N13*5.5 -> 1155 | P13: =I13*0.0425 -> 999.4266 | Q13: =IF(I13>16013,(I13-8020)*0.0425,0) -> 658.5766 | R13: =IF(I13>16013,(I13-16013)*0.051,0) -> 382.64892 | S13: =SUM(P13:R13) -> 2040.6521
B14: FACON | C14: PIERRE | D14: 01/09/1996 | E14: FORMATEUR RESP. SECTEUR | F14: 3327.98 | G14: =2043.91-111-238.2-28.69-165.78-0.59-37.1 -> 1462.55 | H14: =G14/F14 -> 0.43947079 | I14: =F14*12 -> 39935.76 | J14: =H14*I14 -> 17550.6 | N14: =20*10.5 -> 210 | O14: =N14*5.5 -> 1155 | P14: =I14*0.0425 -> 1697.2698 | Q14: =IF(I14>16013,(I14-8020)*0.0425,0) -> 1356.4198 | R14: =IF(I14>16013,(I14-16013)*0.051,0) -> 1220.0608 | S14: =SUM(P14:R14) -> 4273.7504
N15: =20*10.5 -> 210 | O15: =N15*5.5 -> 1155 | P15: =I15*0.0425 -> 0 | Q15: =IF(I15>16013,(I15-8020)*0.0425,0) -> 0 | R15: =IF(I15>16013,(I15-16013)*0.051,0) -> 0 | S15: =SUM(P15:R15) -> 0
B16: FOMBELLE | C16: SABINE | D16: 01/05/2010 | E16: FORMATEUR RESP. SECTEUR | F16: 3410.5 | G16: =1402.8-111-124.49-28.69-114.09-0.41-25.58 -> 998.54 | H16: =G16/F16 -> 0.29278405 | I16: =F16*12 -> 40926 | J16: =H16*I16 -> 11982.48 | N16: =20*10.5 -> 210 | O16: =N16*5.5 -> 1155 | P16: =I16*0.0425 -> 1739.355 | Q16: =IF(I16>16013,(I16-8020)*0.0425,0) -> 1398.505 | R16: =IF(I16>16013,(I16-16013)*0.051,0) -> 1270.563 | S16: =SUM(P16:R16) -> 4408.423
B17: GROLEZ | C17: SANDRINE | D17: 17/02/2014 | E17: COMPTABLE | F17: 2731.3 | G17: =1696.72-111-171.12-28.69-135.28-0.48-29.83 -> 1220.32 | H17: =G17/F17 -> 0.44679091 | I17: =2731.3+G17 -> 3951.62 | J17: =H17*I17 -> 1765.5479 | N17: =20*10.5 -> 210 | O17: =N17*5.5 -> 1155 | P17: =I17*0.0425 -> 167.94385 | Q17: =IF(I17>16013,(I17-8020)*0.0425,0) -> 0 | R17: =IF(I17>16013,(I17-16013)*0.051,0) -> 0 | S17: =SUM(P17:R17) -> 167.94385
B18: LAUDE | C18: MAXIME | D18: 14/01/2019 | E18: TECHNICIEN QUALIFIE | F18: 1997.86 | G18: =1583.57-111-166.85-28.69-133.34-0.47-29.4 -> 1113.82 | H18: 0.3 | I18: =F18*12 -> 23974.32 | J18: =H18*I18 -> 7192.296 | N18: =20*10.5 -> 210 | O18: =N18*5.5 -> 1155 | P18: =I18*0.0425 -> 1018.9086 | Q18: =IF(I18>16013,(I18-8020)*0.0425,0) -> 678.0586 | R18: =IF(I18>16013,(I18-16013)*0.051,0) -> 406.02732 | S18: =SUM(P18:R18) -> 2102.9945
B19: MARTIN | C19: CHRISTELLE | D19: 07/06/2017 | E19: SECRETAIRE ADMINISTRATIVE | F19: 2013.14 | G19: =1439.63-111-138.54-28.69-120.48-0.42-26.54 -> 1013.96 | H19: 0.31 | I19: =F19*12 -> 24157.68 | J19: =H19*I19 -> 7488.8808 | N19: =20*10.5 -> 210 | O19: =N19*5.5 -> 1155 | P19: =I19*0.0425 -> 1026.7014 | Q19: =IF(I19>16013,(I19-8020)*0.0425,0) -> 685.8514 | R19: =IF(I19>16013,(I19-16013)*0.051,0) -> 415.37868 | S19: =SUM(P19:R19) -> 2127.9315
B20: MENIAL | C20: XAVIER | D20: 02/04/1993 | E20: AGENT POLYVALENT | F20: 2731.3 | G20: =1672.05-55.5-176.62-28.69-137.79-0.49-30.38 -> 1242.58 | H20: =G20/F20 -> 0.45494087 | I20: =F20*12 -> 32775.6 | J20: =H20*I20 -> 14910.96 | N20: =20*10.5 -> 210 | O20: =N20*5.5 -> 1155 | P20: =I20*0.0425 -> 1392.963 | Q20: =IF(I20>16013,(I20-8020)*0.0425,0) -> 1052.113 | R20: =IF(I20>16013,(I20-16013)*0.051,0) -> 854.8926 | S20: =SUM(P20:R20) -> 3299.9686
B21: NOUICHI | C21: MUSTAPHA | D21: 01/09/2016 | E21: FORMATEUR RESP. SECTEUR | F21: 3080.45 | G21: =1893.16-111-212.62-28.69-154.15-0.55-34.62 -> 1351.53 | H21: =G21/F21 -> 0.43874434 | I21: =F21*12 -> 36965.4 | J21: =H21*I21 -> 16218.36 | N21: =20*10.5 -> 210 | O21: =N21*5.5 -> 1155 | P21: =I21*0.0425 -> 1571.0295 | Q21: =IF(I21>16013,(I21-8020)*0.0425,0) -> 1230.1795 | R21: =IF(I21>16013,(I21-16013)*0.051,0) -> 1068.5724 | S21: =SUM(P21:R21) -> 3869.7814
B22: POTEAU | C22: ALEXANDRA | D22: 45212 | E22: COMPTABLE | F22: 2446.41 | G22: 1340.2 | H22: =G22/F22 -> 0.54782314 | I22: =F22*12 -> 29356.92 | J22: =H22*I22 -> 16082.4 | P22: =I22*0.0425 -> 1247.6691 | Q22: =IF(I22>16013,(I22-8020)*0.0425,0) -> 906.8191 | R22: =IF(I22>16013,(I22-16013)*0.051,0) -> 680.53992 | S22: =SUM(P22:R22) -> 2835.0281
B23: GILMET | C23: SYLVIE | D23: 45002 | E23: GESTIONNAIRE PAIE | F23: 2417.24 | G23: 1297.21 | H23: =G23/F23 -> 0.53664924 | I23: =F23*12 -> 29006.88 | J23: =H23*I23 -> 15566.52 | O23: =N23*5.5 -> 0 | P23: =I23*0.0425 -> 1232.7924 | Q23: =IF(I23>16013,(I23-8020)*0.0425,0) -> 891.9424 | R23: =IF(I23>16013,(I23-16013)*0.051,0) -> 662.68788 | S23: =SUM(P23:R23) -> 2787.4227
B24: BOUACHRA | C24: KAMEL | D24: 01/09/2022 | E24: FORMATEUR | F24: 3621.89 | G24: 1969.43 | H24: =G24/F24 -> 0.54375754 | I24: =F24*12 -> 43462.68 | J24: =H24*I24 -> 23633.16
B25: TOMMASINI | C25: Marion | D25: 45537 | E25: FORMATEUR | F25: 3151.49 | G25: 2390.5 | H25: =G25/F25 -> 0.75853009 | I25: =F25*12 -> 37817.88 | J25: =H25*I25 -> 28686
B26: MONNIER | C26: MATTHIEU | D26: 45537 | E26: FORMATEUR | F26: 3066.6 | G26: 2324.11 | H26: =G26/F26 -> 0.75787843 | I26: =F26*12 -> 36799.2 | J26: =H26*I26 -> 27889.32
I27: =SUM(I2:I26) -> 735989.3 | J27: =SUM(J2:J26) -> 333358.84 | O27: =SUM(O2:O23) -> 21945 | P27: =SUM(P2:P23) -> 26261.155 | Q27: =SUM(Q2:Q23) -> 19617.062 | R27: =SUM(R2:R23) -> 15795.257 | S27: =SUM(P27:R27) -> 61673.474

Sheet CDD
A1: Période | B1: Nom | C1: Prénom | D1: Date entrée | E1: Date début contrat | F1: Date fin contrat | G1: Emploi | H1: SALAIRE CONTRACTUEL 11/2022 | I1: Charges sociales | J1: Taux de charges | K1: SALAIRES BRUTS 2023 RETENUS | L1: CHARGES SOCIALES 2023 RETENUES | P1: Taxe sur les salaires taux global | Q1: Taux Majo 1er tranche | R1: Taux majo 2e Tranche | S1: Total T.S.
K2: =SUM(#REF!) -> #REF! | L2: =SUM(#REF!) -> #REF! | P2: =SUM(#REF!) -> #REF! | Q2: =SUM(#REF!) -> #REF! | R2: =SUM(#REF!) -> #REF! | S2: =SUM(#REF!) -> #REF!

Sheet Accueil

Sheet MOD
A1: DETAIL MOD - PERMANENTS AFERTES
A2: Nom | B2: Prénom | C2: Statut | D2: Date début | E2: Date Fin | F2: Poste | G2: Filière | H2: Affectation | J2: Temps h/mois | K2: Salaire brut (+2% majo pt) | L2: Cout employeur | M2: Cotis patro
A3: ANDREAU | B3: DIDIER | C3: CDI/CADRE | D3: 36526 | E3: 45473 | F3: FORMATEUR RESP. SECTEUR | G3: FI ES | H3: Formation | J3: 138.13 | K3: 4102.92 | L3: =K3*(1+M3) -> 4102.92 | M3: =CDI!H2 -> 0
A4: BOUACHRA | B4: KAMEL | C4: CDI/CADRE | D4: 45108 | E4: 402133 | F4: FORMATEUR | G4: FI ES | H4: Formation | J4: 69.065 | K4: =+CDI!F24 -> 3621.89 | L4: =K4*(1+M4) -> 5591.32 | M4: =CDI!H24 -> 0.54375754
A5: BRACQ | B5: JEAN JACQUES | C5: CDI/CADRE | D5: 36526 | E5: 402133 | F5: FORMATEUR RESP. SECTEUR | G5: FI ME | H5: Formation | J5: 138.13 | K5: 3949.65 | L5: =K5*(1+M5) -> 5487.8768 | M5: =CDI!H3 -> 0.38945902
A6: BRUXELLE | B6: JOEL | C6: CDI/CADRE | D6: 36526 | E6: 402133 | F6: FORMATEUR | G6: FC | H6: Formation | J6: 103.6 | K6: =2914.49*0.75 -> 2185.8675 | L6: =K6*(1+M6) -> 3015.7436 | M6: =CDI!H4 -> 0.37965524
A7: BRUXELLE | B7: JOEL | C7: CDI/CADRE | D7: 36526 | E7: 402133 | F7: FORMATEUR | G7: FI ME | H7: Formation | J7: 34.53 | K7: =2891.1288-K6 -> 705.2613 | L7: =K7*(1+M7) -> 896.17509 | M7: =CDI!H5 -> 0.27069937
A8: CHRETIEN | B8: CASSANDRA | C8: CDI/NON CADRE | D8: 36526 | E8: 402133 | F8: AGENT DE BUREAU | G8: AUTRE | H8: Documentation | J8: 138.12 | K8: 2045.69 | L8: =K8*(1+M8) -> 2599.457 | M8: =CDI!H5 -> 0.27069937
A9: DELPLANQUE | B9: Margot | C9: APPRENTISSAGE | D9: 36526 | E9: 402133 | F9: APPRENTI | G9: AUTRE | H9: Documentation | I9: Comm | J9: 151.67 | K9: 1170.65 | L9: =K9*(1+M9) -> 1170.65 | M9: =0 -> 0
A10: CSIZMADIA | B10: CELINE | C10: CDI/CADRE | D10: 36526 | E10: 402133 | F10: FORMATRICE | G10: FI ES | H10: Formation | J10: 138.13 | K10: 2805.408 | L10: =K10*(1+M10) -> 3562.8682 | M10: =CDI!H9 -> 0.27
A11: DECOOL | B11: ELODIE | C11: CDI/NON CADRE | D11: 36526 | E11: 402133 | F11: SECRETAIRE ADMINISTRATIVE | G11: FI ES | H11: Administratif | I11: Secrétariat | J11: 138.13 | K11: 2111.1144 | L11: =K11*(1+M11) -> 2681.1153 | M11: 0.27
A12: DEFACQUES | B12: EMILIE | C12: CDI | D12: 45108 | E12: 402134 | F12: FORMATRICE | G12: FI ES | H12: Formation | J12: 138.13 | K12: 2914.49 | L12: =K12*(1+M12) -> 4210.35 | M12: =CDI!H8 -> 0.44462668
A13: DELABIE | B13: CHARLOTTE | C13: CDI/CADRE | D13: 36526 | E13: 402133 | F13: FORMATRICE | G13: AUTRE | H13: Administratif | I13: Direction | J13: 138.13 | K13: 3890.7 | L13: =K13*(1+M13) -> 5704.0499 | M13: =CDI!H11 -> 0.46607292
A14: DUGUE | B14: PIERRE | C14: CDI/CADRE | D14: 36526 | E14: 402133 | F14: FORMATEUR RESP. SECTEUR | G14: FI AVION | H14: Formation | I14: Resp site | J14: 138.13 | K14: 3839.61 | L14: =K14*(1+M14) -> 5939.5629 | M14: =CDI!H12 -> 0.54691829
A15: EVRARD | B15: OLIVIER | C15: CDI/CADRE | D15: 36526 | E15: 402133 | F15: FORMATEUR | G15: FI AVION | H15: Formation | J15: 138.13 | K15: 2805.1717 | L15: =K15*(1+M15) -> 3562.568 | M15: =CDI!H13 -> 0.27
A16: EYZOP | B16: BENEDICTE | C16: CDI/NON CADRE | D16: 36526 | E16: 402133 | F16: AGENT ADMINISTRATIF | G16: FI ME | H16: Administratif | I16: Secrétariat | J16: 138.13 | K16: 2246.8968 | L16: =K16*(1+M16) -> 2853.5589 | M16: 0.27
A17: FACON | B17: PIERRE | C17: CDI/CADRE | D17: 36526 | E17: 402133 | F17: FORMATEUR RESP. SECTEUR | G17: FI ME | H17: Formation | I17: Resp filière | J17: 138.13 | K17: 3816.82 | L17: =K17*(1+M17) -> 5494.2009 | M17: =CDI!H14 -> 0.43947079
A18: FAUQUEMBERGUE | B18: GILLES | C18: CDI/CADRE | D18: 36526 | E18: 402133 | F18: FORMATEUR RESP. SECTEUR | G18: FI ME | H18: Formation | J18: 138.13 | K18: 3621.89 | L18: =K18*(1+M18) -> 3621.89 | M18: =CDI!H15 -> 0
A19: FOMBELLE | B19: SABINE | C19: CDI/CADRE | D19: 36526 | E19: 402133 | F19: FORMATEUR RESP. SECTEUR | G19: FC | H19: Formation | J19: 138.13 | K19: 3508.7 | L19: =K19*(1+M19) -> 4535.9914 | M19: 0.29278405
A20: GILMET | B20: SYLVIE | C20: CDD CUI CAE/NON CADRE | D20: 36526 | E20: 402133 | F20: AGENT ADMINISTRATIF PRINCIPAL | G20: AUTRE | H20: Administratif | I20: Employé polyvalent | J20: 138.13 | K20: 2131.8816 | L20: =K20*(1+M20) -> 3275.9542 | M20: =CDI!H23 -> 0.53664924
A21: GROLEZ | B21: SANDRINE | C21: CDI NON CADRE | D21: 36526 | E21: 44958 | F21: COMPTABLE | G21: AUTRE | H21: Administratif | I21: Compta | J21: 138.13 | K21: 3042.507 | L21: =K21*(1+M21) -> 4401.8715 | M21: 0.44679091
A22: LAUDE | B22: MAXIME | C22: CDI/NON CADRE | D22: 36526 | E22: 402133 | F22: AGENT DE BUREAU | G22: AUTRE | H22: Administratif | I22: Agent accueil | J22: 138.13 | K22: 2290.6956 | L22: =K22*(1+M22) -> 2977.9043 | M22: 0.3
A23: MARTIN | B23: CHRISTELLE | C23: CDI/NON CADRE | D23: 36526 | E23: 402133 | F23: SECRETAIRE ADMINISTRATIVE | G23: AUTRE | H23: Administratif | I23: Assist FC | J23: 138.13 | K23: 2276.7522 | L23: =K23*(1+M23) -> 2982.5454 | M23: 0.31
A24: MENIAL | B24: XAVIER | C24: CDI/NON CADRE | D24: 36526 | E24: 402133 | F24: AGENT POLYVALENT | G24: AUTRE | H24: Administratif | I24: Resp technique | J24: 138.13 | K24: 3099.219 | L24: =K24*(1+M24) -> 4509.1804 | M24: 0.45494087
A25: NOUICHI | B25: MUSTAPHA | C25: CDI/CADRE | D25: 36526 | E25: 402133 | F25: FORMATEUR RESP. SECTEUR | G25: FC | H25: Formation | J25: 138.13 | K25: 3647.04 | L25: =K25*(1+M25) -> 5247.1582 | M25: 0.43874434 | N25: =K11*12 -> 25333.373
A26: POTEAU | B26: Alexandra | C26: CDI | D26: 44958 | E26: 402134 | F26: COMPTABLE | G26: AUTRE | H26: Administratif | J26: 138.13 | K26: 2446.41 | L26: =K26*(1+M26) -> 3767.4714 | M26: 0.54 | N26: =K16*12 -> 26962.762
A27: COUVILLERS | B27: Laurent | C27: CDI/CADRE | D27: 45323 | E27: 402133 | F27: FORMATEUR/ chargé de developpement | G27: FC | H27: Formation | J27: 97 | K27: 2548.8 | L27: =K27*(1+M27) -> 3517.344 | M27: 0.38 | N27: =K20*12 -> 25582.579
A28: XXX | B28: XXX | C28: CDI/NON CADRE | D28: 45292 | E28: 402133 | F28: AGENT DE MENAGE | G28: AUTRE | I28: Femme de ménage | J28: 138.13 | K28: 1800 | L28: =K28*(1+M28) -> 2250 | M28: 0.25 | N28: =N27/2 -> 12791.29
A29: CORMONT | B29: Olivier | C29: CDI/CAFRE | D29: 36526 | E29: 402133 | F29: RESP DOC | G29: AUTRE | H29: Documentation | J29: 138.13 | K29: 4118.2 | L29: =K29*(1+M29) -> 5147.75 | M29: 0.25 | N29: =K23*12 -> 27321.026
A30: TOMMASINI | B30: Marion | C30: CDI/CADRE | D30: 45537 | E30: 402133 | F30: FORMATEUR RESP. SECTEUR | G30: FI ME | H30: Formation | J30: 138.13 | K30: 3151.49 | L30: =K30*(1+M30) -> 5541.99 | M30: =+CDI!H25 -> 0.75853009 | N30: =(K22+N28+K13+K26)*12 -> 257029.14
A31: MONNIER | B31: Matthieu | C31: CDI/CADRE | D31: 45537 | E31: 402133 | F31: FORMATEUR RESP. SECTEUR | G31: FI ES | H31: Formation | J31: 138.13 | K31: 3066.6 | L31: =K31*(1+M31) -> 5390.71 | M31: =+CDI!H26 -> 0.75787843
L32: =K32*(1+M32) -> 0
K35: Tx moyens cotis' pro | L35: Formation | M35: =AVERAGEIF($H$3:$H$25,L35,$M$3:$M$25)-0.02 -> 0.30970118
L36: Administratif | M36: =AVERAGEIF($H$3:$H$25,L36,$M$3:$M$25)+0.03 -> 0.41180674 | N36: =(K11+K13+K20+K23+K22+K26)*12 -> 181770.65
L37: Documentation | M37: =AVERAGEIF($H$3:$H$25,L37,$M$3:$M$25) -> 0.13534968
K41: =SUM(K3:K29) -> 76744.235 | L41: =K41*0.22 -> 16883.732 | M41: =K41-L41 -> 59860.503 | N41: =K24*12 -> 37190.628
K42: =K41*12 -> 920930.82 | M42: =M41*12 -> 718326.04
E44: VERIF MANUELLE (attention obsolète si modif hyp. post 21/12/2022) :
E45: janv | F45: =75430*1.02 -> 76938.6 | I45: =SUM('Hypotheses expl'!C143:C144)-F45 -> -13525.955
E46: fevr->juin inclus | F46: =F45-3162*1.02 -> 73713.36 | I46: =SUM('Hypotheses expl'!D143:D144)-F46 -> -10896.812
...

Sheet Hypotheses expl
A1: Début du prévisionnel | B1: 44927 | Q1: X | R1: Section à affecter 1 | S1: Montant | T1: Section à affecter 2 | U1: Montant | V1: Section à affecter 3 | W1: Montant | X1: Section à affecter 4 | Y1: Montant | Z1: Section à affecter 5 | AA1: Montant | AB1: Section à affecter 6 | AC1: Montant
A2: HYPOTHESES D'EXPLOITATION
C3: =B1 -> 44927 | D3: =DATE(YEAR(C3),MONTH(C3)+1,DAY(C3)) -> 44958 | E3: =DATE(YEAR(D3),MONTH(D3)+1,DAY(D3)) -> 44986 | F3: =DATE(YEAR(E3),MONTH(E3)+1,DAY(E3)) -> 45017 | G3: =DATE(YEAR(F3),MONTH(F3)+1,DAY(F3)) -> 45047 | H3: =DATE(YEAR(G3),MONTH(G3)+1,DAY(G3)) -> 45078 | I3: =DATE(YEAR(H3),MONTH(H3)+1,DAY(H3)) -> 45108 | J3: =DATE(YEAR(I3),MONTH(I3)+1,DAY(I3)) -> 45139 | K3: =DATE(YEAR(J3),MONTH(J3)+1,DAY(J3)) -> 45170 | ... N3: =DATE(YEAR(M3),MONTH(M3)+1,DAY(M3)) -> 45261 | O3: TOTAL ANNUEL | P3: Modalités paiement | Q3: Alerte
C5: RYTHME D'ENGAGEMENT
A6: Détermination de Chiffre d'Affaires (€) | C6: =C3 -> 44927 | D6: =D3 -> 44958 | E6: =E3 -> 44986 | F6: =F3 -> 45017 | G6: =G3 -> 45047 | H6: =H3 -> 45078 | I6: =I3 -> 45108 | J6: =J3 -> 45139 | ... N6: =N3 -> 45261 | O6: TOTAL ANNUEL
A7: Droits d'inscription
A8: Prix moyen (en €) | B8: Quantités
A9: 1 | B9: 1 | K9: =146300*0.7 -> 102410 | L9: =146300*0.2 -> 29260 | M9: =146300*0.1 -> 14630 | O9: =SUM(C9:N9)-40000 -> 106300
C10: =$A$9*C9 -> 0 | D10: =$A$9*D9 -> 0 | E10: =$A$9*E9 -> 0 | F10: =$A$9*F9 -> 0 | G10: =$A$9*G9 -> 0 | H10: =$A$9*H9 -> 0 | I10: =$A$9*I9 -> 0 | J10: =$A$9*J9 -> 0 | ... N10: =$A$9*N9 -> 0 | O10: =SUM(C10:N10)-40000 -> 106300 | P10: 0j | Q10: =IF(ROUND(O10,0)<>ROUND(SUM(S10,U10,W10,Y10,AA10,AC10),0),"x","") | R10: FI ES | S10: =42*(190*3)+42*(410*3)-20669 -> 54931 | T10: FI ME | U10: =100*(190*2)-10390 -> 27610 | V10: FI AVION | W10: =15*(190*2)+15*(190*3)+15*(410*3)-8941 -> 23759
A11: Frais de selection
A12: Prix moyen (en €) | B12: Quantités
A13: 1 | G13: =42800*0.6 -> 25680 | H13: =42800*0.4 -> 17120 | O13: =SUM(C13:N13) -> 42800
C14: =+$A$13*C13 -> 0 | D14: =+$A$13*D13 -> 0 | E14: =+$A$13*E13 -> 0 | F14: =+$A$13*F13 -> 0 | G14: =+$A$13*G13 -> 25680 | H14: =+$A$13*H13 -> 17120 | I14: =+$A$13*I13 -> 0 | J14: =+$A$13*J13 -> 0 | ... N14: =+$A$13*N13 -> 0 | O14: =SUM(C14:N14) -> 42800 | P14: 0j | Q14: =IF(O14<>SUM(S14,U14,W14,Y14,AA14,AC14),"x","") | R14: FI ES | S14: =42*(80)/0.4 -> 8400 | T14: FI ME | U14: =(100*0.5*(60+80)+100*0.5*(80))/0.4 -> 27500 | V14: FI AVION | W14: =(15*(80)+15*0.4*(60+80)+15*0.6*(80))/0.4 -> 6900
A15: Conventions formation (CAFERUIS, ALEFPA, Prepa, CNFPT, GAP, Formation perm)
A16: Prix moyen (en €) | B16: Quantités
A17: 1 | B17: 1 | L17: 50000 | N17: =218021-L17 -> 168021 | O17: =SUM(C17:N17) -> 218021
C18: =+$A$17*C17 -> 0 | D18: =+$A$17*D17 -> 0 | E18: =+$A$17*E17 -> 0 | F18: =+$A$17*F17 -> 0 | G18: =+$A$17*G17 -> 0 | H18: =+$A$17*H17 -> 0 | I18: =+$A$17*I17 -> 0 | J18: =+$A$17*J17 -> 0 | ... N18: =+$A$17*N17 -> 168021 | O18: =SUM(C18:N18) -> 218021 | P18: 0j | Q18: =IF(O18<>SUM(S18,U18,W18,Y18,AA18,AC18),"x","") | R18: FC | S18: =O18 -> 218021
A19: Conventions formation CAFERUISE
A20: Prix moyen (en €) | B20: Quantités
O21: =SUM(C21:N21) -> 0
C22: =$A$21*C21 -> 0 | D22: =$A$21*D21 -> 0 | E22: =$A$21*E21 -> 0 | F22: =$A$21*F21 -> 0 | G22: =$A$21*G21 -> 0 | H22: =$A$21*H21 -> 0 | I22: =$A$21*I21 -> 0 | J22: =$A$21*J21 -> 0 | ... N22: =$A$21*N21 -> 0 | O22: =SUM(C22:N22) -> 0 | P22: 0j | Q22: =IF(O22<>SUM(S22,U22,W22,Y22,AA22,AC22),"x","") | R22: Structure | S22: =O22 -> 0
A23: Apprentissage
A24: Prix moyen (en €) | B24: Quantités
A25: 1 | B25: 1 | D25: 20365 | H25: 22348 | L25: 12489 | N25: 4306 | O25: =SUM(C25:N25) -> 59508
C26: =C25*$A$25 -> 0 | D26: =D25*$A$25 -> 20365 | E26: =E25*$A$25 -> 0 | F26: =F25*$A$25 -> 0 | G26: =G25*$A$25 -> 0 | H26: =H25*$A$25 -> 22348 | I26: =I25*$A$25 -> 0 | J26: =J25*$A$25 -> 0 | ... N26: =N25*$A$25 -> 4306 | O26: =SUM(C26:N26) -> 59508 | P26: 0j | Q26: =IF(O26<>SUM(S26,U26,W26,Y26,AA26,AC26),"x","") | R26: FC | S26: =O26 -> 59508
A27: VAE
A28: Prix moyen (en €) | B28: Quantités
A29: 1 | B29: 1 | N29: 33000 | O29: =SUM(C29:N29) -> 33000
C30: =+C29*$A$29 -> 0 | D30: =+D29*$A$29 -> 0 | E30: =+E29*$A$29 -> 0 | F30: =+F29*$A$29 -> 0 | G30: =+G29*$A$29 -> 0 | H30: =+H29*$A$29 -> 0 | I30: =+I29*$A$29 -> 0 | J30: =+J29*$A$29 -> 0 | ... N30: =+N29*$A$29 -> 33000 | O30: =SUM(C30:N30) -> 33000 | P30: 0j | Q30: =IF(O30<>SUM(S30,U30,W30,Y30,AA30,AC30),"x","") | R30: FC | S30: =O30 -> 33000
A31: Formation continue - micro formation
A32: Prix moyen (en €) | B32: Quantités
O33: =SUM(C33:N33) -> 0
C34: =$A$33*C33 -> 0 | D34: =$A$33*D33 -> 0 | E34: =$A$33*E33 -> 0 | F34: =$A$33*F33 -> 0 | G34: =$A$33*G33 -> 0 | H34: =$A$33*H33 -> 0 | I34: =$A$33*I33 -> 0 | J34: =$A$33*J33 -> 0 | ... O34: =$A$33*O33 -> 0 | P34: 0j | Q34: =IF(O34<>SUM(S34,U34,W34,Y34,AA34,AC34),"x","") | R34: Structure | S34: =O34 -> 0
A35: DSB
A36: Prix moyen (en €) | B36: Quantités
A37: 1 | B37: 1 | N37: 8400 | O37: =SUM(C37:N37) -> 8400
C38: =+$A$37*C37 -> 0 | D38: =+$A$37*D37 -> 0 | E38: =+$A$37*E37 -> 0 | F38: =+$A$37*F37 -> 0 | G38: =+$A$37*G37 -> 0 | H38: =+$A$37*H37 -> 0 | I38: =+$A$37*I37 -> 0 | J38: =+$A$37*J37 -> 0 | ... O38: =+$A$37*O37 -> 8400 | P38: 0j | Q38: =IF(O38<>SUM(S38,U38,W38,Y38,AA38,AC38),"x","") | R38: FC | S38: =O38 -> 8400
A39: Autres segments de CA
A40: Prix moyen (en €) | B40: Quantités
O41: =SUM(C41:N41) -> 0
...

Sheet Hypotheses expl (3,)
A1: Début du prévisionnel | B1: 45658 | Q1: X | R1: Section à affecter 1 | S1: Montant | T1: Section à affecter 2 | U1: Montant | V1: Section à affecter 3 | W1: Montant | X1: Section à affecter 4 | Y1: Montant | Z1: Section à affecter 5 | AA1: Montant | AB1: Section à affecter 6 | AC1: Montant
A2: HYPOTHESES D'EXPLOITATION
C3: =B1 -> 45658 | D3: =DATE(YEAR(C3),MONTH(C3)+1,DAY(C3)) -> 45689 | E3: =DATE(YEAR(D3),MONTH(D3)+1,DAY(D3)) -> 45717 | F3: =DATE(YEAR(E3),MONTH(E3)+1,DAY(E3)) -> 45748 | G3: =DATE(YEAR(F3),MONTH(F3)+1,DAY(F3)) -> 45778 | H3: =DATE(YEAR(G3),MONTH(G3)+1,DAY(G3)) -> 45809 | I3: =DATE(YEAR(H3),MONTH(H3)+1,DAY(H3)) -> 45839 | J3: =DATE(YEAR(I3),MONTH(I3)+1,DAY(I3)) -> 45870 | K3: =DATE(YEAR(J3),MONTH(J3)+1,DAY(J3)) -> 45901 | ... N3: =DATE(YEAR(M3),MONTH(M3)+1,DAY(M3)) -> 45992 | O3: TOTAL ANNUEL | P3: Modalités paiement | Q3: Alerte
C5: RYTHME D'ENGAGEMENT
A6: Détermination de Chiffre d'Affaires (€) | C6: =C3 -> 45658 | D6: =D3 -> 45689 | E6: =E3 -> 45717 | F6: =F3 -> 45748 | G6: =G3 -> 45778 | H6: =H3 -> 45809 | I6: =I3 -> 45839 | J6: =J3 -> 45870 | ... N6: =N3 -> 45992 | O6: TOTAL ANNUEL
A7: Droits d'inscription
A8: Prix moyen (en €) | B8: Quantités
A9: 1 | B9: 1 | K9: =146300*0.7 -> 102410 | L9: =146300*0.2 -> 29260 | M9: =146300*0.1 -> 14630 | O9: =SUM(C9:N9)-40000 -> 106300
C10: =$A$9*C9 -> 0 | D10: =$A$9*D9 -> 0 | E10: =$A$9*E9 -> 0 | F10: =$A$9*F9 -> 0 | G10: =$A$9*G9 -> 0 | H10: =$A$9*H9 -> 0 | I10: =$A$9*I9 -> 0 | J10: =$A$9*J9 -> 0 | ... N10: =$A$9*N9 -> 0 | O10: =SUM(C10:N10)-40000 -> 106300 | P10: 0j | Q10: =IF(ROUND(O10,0)<>ROUND(SUM(S10,U10,W10,Y10,AA10,AC10),0),"x","") | R10: FI ES | S10: =42*(190*3)+42*(410*3)-20669 -> 54931 | T10: FI ME | U10: =100*(190*2)-10390 -> 27610 | V10: FI AVION | W10: =15*(190*2)+15*(190*3)+15*(410*3)-8941 -> 23759
A11: Frais de selection
A12: Prix moyen (en €) | B12: Quantités
A13: 1 | H13: 25680 | O13: =SUM(C13:N13) -> 25680
C14: =+$A$13*C13 -> 0 | D14: =+$A$13*D13 -> 0 | E14: =+$A$13*E13 -> 0 | F14: =+$A$13*F13 -> 0 | G14: =+$A$13*G13 -> 0 | H14: =+$A$13*H13 -> 25680 | I14: =+$A$13*I13 -> 0 | J14: =+$A$13*J13 -> 0 | ... N14: =+$A$13*N13 -> 0 | O14: =SUM(C14:N14) -> 25680 | P14: 0j | Q14: =IF(O14<>SUM(S14,U14,W14,Y14,AA14,AC14),"x","") | R14: FI ES | S14: =42*(80)/0.4 -> 8400 | T14: FI ME | U14: 10380 | V14: FI AVION | W14: =(15*(80)+15*0.4*(60+80)+15*0.6*(80))/0.4 -> 6900
A15: Conventions formation (CAFERUIS, ALEFPA, Prepa, GAP, Formation perm)
A16: Prix moyen (en €) | B16: Quantités | T16: FI ES
A17: 1 | B17: 1 | L17: 19500 | N17: =218021-L17 -> 198521 | O17: =SUM(C17:N17) -> 218021
C18: =+$A$17*C17 -> 0 | D18: =+$A$17*D17 -> 0 | E18: =+$A$17*E17 -> 0 | F18: =+$A$17*F17 -> 0 | G18: =+$A$17*G17 -> 0 | H18: =+$A$17*H17 -> 0 | I18: =+$A$17*I17 -> 0 | J18: =+$A$17*J17 -> 0 | ... N18: =+$A$17*N17 -> 198521 | O18: =SUM(C18:N18) -> 218021 | P18: 0j | Q18: =IF(O18<>SUM(S18,U18,W18,Y18,AA18,AC18),"x","") | R18: FC | S18: =O18 -> 218021
A19: Conventions formation CAFERUIS
A20: Prix moyen (en €) | B20: Quantités
H21: 40750 | N21: 40750 | O21: =SUM(C21:N21) -> 81500
C22: =$A$21*C21 -> 0 | D22: =$A$21*D21 -> 0 | E22: =$A$21*E21 -> 0 | F22: =$A$21*F21 -> 0 | G22: =$A$21*G21 -> 0 | H22: =$A$21*H21 -> 0 | I22: =$A$21*I21 -> 0 | J22: =$A$21*J21 -> 0 | ... M22: =$A$21*M21 -> 0 | N22: =+N21 -> 40750 | O22: =+O21 -> 81500 | P22: 0j | Q22: =IF(O22<>SUM(S22,U22,W22,Y22,AA22,AC22),"x","") | R22: FC | S22: =O22 -> 81500
A23: Apprentissage
A24: Prix moyen (en €) | B24: Quantités
A25: 1 | B25: 1 | D25: 15000 | H25: 15000 | L25: 15000 | N25: 60000 | O25: =SUM(C25:N25) -> 105000
C26: =C25*$A$25 -> 0 | D26: =D25*$A$25 -> 15000 | E26: =E25*$A$25 -> 0 | F26: =F25*$A$25 -> 0 | G26: =G25*$A$25 -> 0 | H26: =H25*$A$25 -> 15000 | I26: =I25*$A$25 -> 0 | J26: =J25*$A$25 -> 0 | ... N26: =N25*$A$25 -> 60000 | O26: =SUM(C26:N26) -> 105000 | P26: 0j | Q26: =IF(O26<>SUM(S26,U26,W26,Y26,AA26,AC26),"x","") | R26: FC | S26: =O26 -> 105000
A27: VAE
A28: Prix moyen (en €) | B28: Quantités
A29: 1 | B29: 1 | N29: 38864 | O29: =SUM(C29:N29) -> 38864
C30: =+C29*$A$29 -> 0 | D30: =+D29*$A$29 -> 0 | E30: =+E29*$A$29 -> 0 | F30: =+F29*$A$29 -> 0 | G30: =+G29*$A$29 -> 0 | H30: =+H29*$A$29 -> 0 | I30: =+I29*$A$29 -> 0 | J30: =+J29*$A$29 -> 0 | ... N30: =+N29*$A$29 -> 38864 | O30: =SUM(C30:N30) -> 38864 | P30: 0j | Q30: =IF(O30<>SUM(S30,U30,W30,Y30,AA30,AC30),"x","") | R30: FC | S30: =O30 -> 38864
A31: Formation continue - micro formation
A32: Prix moyen (en €) | B32: Quantités
O33: =SUM(C33:N33) -> 0
C34: =$A$33*C33 -> 0 | D34: =$A$33*D33 -> 0 | E34: =$A$33*E33 -> 0 | F34: =$A$33*F33 -> 0 | G34: =$A$33*G33 -> 0 | H34: =$A$33*H33 -> 0 | I34: =$A$33*I33 -> 0 | J34: =$A$33*J33 -> 0 | ... O34: =$A$33*O33 -> 0 | P34: 0j | Q34: =IF(O34<>SUM(S34,U34,W34,Y34,AA34,AC34),"x","") | R34: Structure | S34: =O34 -> 0
A35: DSB
A36: Prix moyen (en €) | B36: Quantités
A37: 1 | B37: 1 | N37: 0 | O37: =SUM(C37:N37) -> 0
C38: =+$A$37*C37 -> 0 | D38: =+$A$37*D37 -> 0 | E38: =+$A$37*E37 -> 0 | F38: =+$A$37*F37 -> 0 | G38: =+$A$37*G37 -> 0 | H38: =+$A$37*H37 -> 0 | I38: =+$A$37*I37 -> 0 | J38: =+$A$37*J37 -> 0 | ... O38: =+$A$37*O37 -> 0 | P38: 0j | Q38: =IF(O38<>SUM(S38,U38,W38,Y38,AA38,AC38),"x","") | R38: FC | S38: =O38 -> 0
A39: Autres segments de CA
A40: Prix moyen (en €) | B40: Quantités
O41: =SUM(C41:N41) -> 0
...

Sheet Hypotheses expl (2)
A1: Début du prévisionnel | B1: 45292 | Q1: X | R1: Section à affecter 1 | S1: Montant | T1: Section à affecter 2 | U1: Montant | V1: Section à affecter 3 | W1: Montant | X1: Section à affecter 4 | Y1: Montant | Z1: Section à affecter 5 | AA1: Montant | AB1: Section à affecter 6 | AC1: Montant
A2: HYPOTHESES D'EXPLOITATION
C3: =B1 -> 45292 | D3: =DATE(YEAR(C3),MONTH(C3)+1,DAY(C3)) -> 45323 | E3: =DATE(YEAR(D3),MONTH(D3)+1,DAY(D3)) -> 45352 | F3: =DATE(YEAR(E3),MONTH(E3)+1,DAY(E3)) -> 45383 | G3: =DATE(YEAR(F3),MONTH(F3)+1,DAY(F3)) -> 45413 | H3: =DATE(YEAR(G3),MONTH(G3)+1,DAY(G3)) -> 45444 | I3: =DATE(YEAR(H3),MONTH(H3)+1,DAY(H3)) -> 45474 | J3: =DATE(YEAR(I3),MONTH(I3)+1,DAY(I3)) -> 45505 | K3: =DATE(YEAR(J3),MONTH(J3)+1,DAY(J3)) -> 45536 | ... N3: =DATE(YEAR(M3),MONTH(M3)+1,DAY(M3)) -> 45627 | O3: TOTAL ANNUEL | P3: Modalités paiement | Q3: Alerte
C5: RYTHME D'ENGAGEMENT
A6: Détermination de Chiffre d'Affaires (€) | C6: =C3 -> 45292 | D6: =D3 -> 45323 | E6: =E3 -> 45352 | F6: =F3 -> 45383 | G6: =G3 -> 45413 | H6: =H3 -> 45444 | I6: =I3 -> 45474 | J6: =J3 -> 45505 | ... N6: =N3 -> 45627 | O6: TOTAL ANNUEL
A7: Droits d'inscription
A8: Prix moyen (en €) | B8: Quantités
A9: 1 | B9: 1 | K9: =146300*0.7 -> 102410 | L9: =146300*0.2 -> 29260 | M9: =146300*0.1 -> 14630 | O9: =SUM(C9:N9)-40000 -> 106300
C10: =$A$9*C9 -> 0 | D10: =$A$9*D9 -> 0 | E10: =$A$9*E9 -> 0 | F10: =$A$9*F9 -> 0 | G10: =$A$9*G9 -> 0 | H10: =$A$9*H9 -> 0 | I10: =$A$9*I9 -> 0 | J10: =$A$9*J9 -> 0 | ... N10: =$A$9*N9 -> 0 | O10: =SUM(C10:N10)-40000 -> 106300 | P10: 0j | Q10: =IF(ROUND(O10,0)<>ROUND(SUM(S10,U10,W10,Y10,AA10,AC10),0),"x","") | R10: FI ES | S10: =42*(190*3)+42*(410*3)-20669 -> 54931 | T10: FI ME | U10: =100*(190*2)-10390 -> 27610 | V10: FI AVION | W10: =15*(190*2)+15*(190*3)+15*(410*3)-8941 -> 23759
A11: Frais de selection
A12: Prix moyen (en €) | B12: Quantités
A13: 1 | G13: =42800*0.6 -> 25680 | O13: =SUM(C13:N13) -> 25680
C14: =+$A$13*C13 -> 0 | D14: =+$A$13*D13 -> 0 | E14: =+$A$13*E13 -> 0 | F14: =+$A$13*F13 -> 0 | G14: =+$A$13*G13 -> 25680 | H14: =+$A$13*H13 -> 0 | I14: =+$A$13*I13 -> 0 | J14: =+$A$13*J13 -> 0 | ... N14: =+$A$13*N13 -> 0 | O14: =SUM(C14:N14) -> 25680 | P14: 0j | Q14: =IF(O14<>SUM(S14,U14,W14,Y14,AA14,AC14),"x","") | R14: FI ES | S14: =42*(80)/0.4 -> 8400 | T14: FI ME | U14: 10380 | V14: FI AVION | W14: =(15*(80)+15*0.4*(60+80)+15*0.6*(80))/0.4 -> 6900
A15: Conventions formation (CAFERUIS, ALEFPA, Prepa, CNFPT, GAP, Formation perm)
A16: Prix moyen (en €) | B16: Quantités
A17: 1 | B17: 1 | L17: 50000 | N17: =218021-L17 -> 168021 | O17: =SUM(C17:N17) -> 218021
C18: =+$A$17*C17 -> 0 | D18: =+$A$17*D17 -> 0 | E18: =+$A$17*E17 -> 0 | F18: =+$A$17*F17 -> 0 | G18: =+$A$17*G17 -> 0 | H18: =+$A$17*H17 -> 0 | I18: =+$A$17*I17 -> 0 | J18: =+$A$17*J17 -> 0 | ... N18: =+$A$17*N17 -> 168021 | O18: =SUM(C18:N18) -> 218021 | P18: 0j | Q18: =IF(O18<>SUM(S18,U18,W18,Y18,AA18,AC18),"x","") | R18: FC | S18: =O18 -> 218021
A19: Conventions formation CAFERUISE
A20: Prix moyen (en €) | B20: Quantités
O21: =SUM(C21:N21) -> 0
C22: =$A$21*C21 -> 0 | D22: =$A$21*D21 -> 0 | E22: =$A$21*E21 -> 0 | F22: =$A$21*F21 -> 0 | G22: =$A$21*G21 -> 0 | H22: =$A$21*H21 -> 0 | I22: =$A$21*I21 -> 0 | J22: =$A$21*J21 -> 0 | ... N22: =$A$21*N21 -> 0 | O22: =SUM(C22:N22) -> 0 | P22: 0j | Q22: =IF(O22<>SUM(S22,U22,W22,Y22,AA22,AC22),"x","") | R22: Structure | S22: =O22 -> 0
A23: Apprentissage
A24: Prix moyen (en €) | B24: Quantités
A25: 1 | B25: 1 | D25: 20000 | H25: 45000 | L25: 5000 | N25: 60000 | O25: =SUM(C25:N25) -> 130000
C26: =C25*$A$25 -> 0 | D26: =D25*$A$25 -> 20000 | E26: =E25*$A$25 -> 0 | F26: =F25*$A$25 -> 0 | G26: =G25*$A$25 -> 0 | H26: =H25*$A$25 -> 45000 | I26: =I25*$A$25 -> 0 | J26: =J25*$A$25 -> 0 | ... N26: =N25*$A$25 -> 60000 | O26: =SUM(C26:N26) -> 130000 | P26: 0j | Q26: =IF(O26<>SUM(S26,U26,W26,Y26,AA26,AC26),"x","") | R26: FC | S26: =O26 -> 130000
A27: VAE
A28: Prix moyen (en €) | B28: Quantités
A29: 1 | B29: 1 | N29: 38864 | O29: =SUM(C29:N29) -> 38864
C30: =+C29*$A$29 -> 0 | D30: =+D29*$A$29 -> 0 | E30: =+E29*$A$29 -> 0 | F30: =+F29*$A$29 -> 0 | G30: =+G29*$A$29 -> 0 | H30: =+H29*$A$29 -> 0 | I30: =+I29*$A$29 -> 0 | J30: =+J29*$A$29 -> 0 | ... N30: =+N29*$A$29 -> 38864 | O30: =SUM(C30:N30) -> 38864 | P30: 0j | Q30: =IF(O30<>SUM(S30,U30,W30,Y30,AA30,AC30),"x","") | R30: FC | S30: =O30 -> 38864
A31: Formation continue - micro formation
A32: Prix moyen (en €) | B32: Quantités
G33: =120000/4 -> 30000 | J33: =120000/4 -> 30000 | L33: =120000/4 -> 30000 | N33: =120000/4 -> 30000 | O33: =SUM(C33:N33) -> 120000
C34: =$A$33*C33 -> 0 | D34: =$A$33*D33 -> 0 | E34: =$A$33*E33 -> 0 | F34: =$A$33*F33 -> 0 | G34: =$A$33*G33 -> 0 | H34: =$A$33*H33 -> 0 | I34: =$A$33*I33 -> 0 | J34: =$A$33*J33 -> 0 | ... M34: =$A$33*M33 -> 0 | N34: =N33 -> 30000 | O34: =O33 -> 120000 | P34: 0j | Q34: =IF(O34<>SUM(S34,U34,W34,Y34,AA34,AC34),"x","") | R34: Structure | S34: =O34 -> 120000
A35: DSB
A36: Prix moyen (en €) | B36: Quantités
A37: 1 | B37: 1 | O37: =SUM(C37:N37) -> 0
C38: =+$A$37*C37 -> 0 | D38: =+$A$37*D37 -> 0 | E38: =+$A$37*E37 -> 0 | F38: =+$A$37*F37 -> 0 | G38: =+$A$37*G37 -> 0 | H38: =+$A$37*H37 -> 0 | I38: =+$A$37*I37 -> 0 | J38: =+$A$37*J37 -> 0 | ... O38: =+$A$37*O37 -> 0 | P38: 0j | Q38: =IF(O38<>SUM(S38,U38,W38,Y38,AA38,AC38),"x","") | R38: FC | S38: =O38 -> 0
A39: Autres segments de CA
A40: Prix moyen (en €) | B40: Quantités
O41: =SUM(C41:N41) -> 0
...

Sheet Hypotheses hors expl
A1: Début du prévisionnel | B1: ='Hypotheses expl'!B1 -> 44927
A2: HYPOTHESES HORS EXPLOITATION
C3: =B1 -> 44927 | D3: =DATE(YEAR(C3),MONTH(C3)+1,DAY(C3)) -> 44958 | E3: =DATE(YEAR(D3),MONTH(D3)+1,DAY(D3)) -> 44986 | F3: =DATE(YEAR(E3),MONTH(E3)+1,DAY(E3)) -> 45017 | G3: =DATE(YEAR(F3),MONTH(F3)+1,DAY(F3)) -> 45047 | H3: =DATE(YEAR(G3),MONTH(G3)+1,DAY(G3)) -> 45078 | I3: =DATE(YEAR(H3),MONTH(H3)+1,DAY(H3)) -> 45108 | J3: =DATE(YEAR(I3),MONTH(I3)+1,DAY(I3)) -> 45139 | K3: =DATE(YEAR(J3),MONTH(J3)+1,DAY(J3)) -> 45170 | ... N3: =DATE(YEAR(M3),MONTH(M3)+1,DAY(M3)) -> 45261
A4: Ressources
A5: Apport associatif
A6: Emprunt
A7: Autres
A9: Besoins
A10: Investissement
A11: Remboursement emprunt | E11: 60000
A12: TVA due (fonctionnement courant) | C12: =IFERROR('Compte résultat prévi'!$C$156*(SUM('Hypotheses expl'!C10,'Hypotheses expl'!C14,'Hypotheses expl'!C18,'Hypotheses expl'!C22,'Hypotheses expl'!C26,'Hypotheses expl'!C30,'Hypotheses expl'!C34,'Hypotheses expl'!C42,'Hypotheses expl'!C38,'Hypotheses expl'!C46,'Hypotheses expl'!C50,'Hypotheses expl'!C54,'Hypotheses expl'!C58,'Hypotheses expl'!C62,'Hypotheses expl'!C66)/SUM('Hypotheses expl'!$O$10,'Hypotheses expl'!$O$14,'Hypotheses expl'!$O$18,'Hypotheses expl'!$O$22,'Hypotheses expl'!$O$26,'Hypotheses expl'!$O$30,'Hypotheses expl'!$O$34,'Hypotheses expl'!$O$42,'Hypotheses expl'!$O$38,'Hypotheses expl'!$O$46,'Hypotheses expl'!$O$50,'Hypotheses expl'!$O$54,'Hypotheses expl'!$O$58,'Hypotheses expl'!$O$62,'Hypotheses expl'!$O$66)),0) -> 0 | D12: =IFERROR('Compte résultat prévi'!$C$156*(SUM('Hypotheses expl'!D10,'Hypotheses expl'!D14,'Hypotheses expl'!D18,'Hypotheses expl'!D22,'Hypotheses expl'!D26,'Hypotheses expl'!D30,'Hypotheses expl'!D34,'Hypotheses expl'!D42,'Hypotheses expl'!D38,'Hypotheses expl'!D46,'Hypotheses expl'!D50,'Hypotheses expl'!D54,'Hypotheses expl'!D58,'Hypotheses expl'!D62,'Hypotheses expl'!D66)/SUM('Hypotheses expl'!$O$10,'Hypotheses expl'!$O$14,'Hypotheses expl'!$O$18,'Hypotheses expl'!$O$22,'Hypotheses expl'!$O$26,'Hypotheses expl'!$O$30,'Hypotheses expl'!$O$34,'Hypotheses expl'!$O$42,'Hypotheses expl'!$O$38,'Hypotheses expl'!$O$46,'Hypotheses expl'!$O$50,'Hypotheses expl'!$O$54,'Hypotheses expl'!$O$58,'Hypotheses expl'!$O$62,'Hypotheses expl'!$O$66)),0) -> 0 | E12: =IFERROR('Compte résultat prévi'!$C$156*(SUM('Hypotheses expl'!E10,'Hypotheses expl'!E14,'Hypotheses expl'!E18,'Hypotheses expl'!E22,'Hypotheses expl'!E26,'Hypotheses expl'!E30,'Hypotheses expl'!E34,'Hypotheses expl'!E42,'Hypotheses expl'!E38,'Hypotheses expl'!E46,'Hypotheses expl'!E50,'Hypotheses expl'!E54,'Hypotheses expl'!E58,'Hypotheses expl'!E62,'Hypotheses expl'!E66)/SUM('Hypotheses expl'!$O$10,'Hypotheses expl'!$O$14,'Hypotheses expl'!$O$18,'Hypotheses expl'!$O$22,'Hypotheses expl'!$O$26,'Hypotheses expl'!$O$30,'Hypotheses expl'!$O$34,'Hypotheses expl'!$O$42,'Hypotheses expl'!$O$38,'Hypotheses expl'!$O$46,'Hypotheses expl'!$O$50,'Hypotheses expl'!$O$54,'Hypotheses expl'!$O$58,'Hypotheses expl'!$O$62,'Hypotheses expl'!$O$66)),0) -> 0 | F12: =IFERROR('Compte résultat prévi'!$C$156*(SUM('Hypotheses expl'!F10,'Hypotheses expl'!F14,'Hypotheses expl'!F18,'Hypotheses expl'!F22,'Hypotheses expl'!F26,'Hypotheses expl'!F30,'Hypotheses expl'!F34,'Hypotheses expl'!F42,'Hypotheses expl'!F38,'Hypotheses expl'!F46,'Hypotheses expl'!F50,'Hypotheses expl'!F54,'Hypotheses expl'!F58,'Hypotheses expl'!F62,'Hypotheses expl'!F66)/SUM('Hypotheses expl'!$O$10,'Hypotheses expl'!$O$14,'Hypotheses expl'!$O$18,'Hypotheses expl'!$O$22,'Hypotheses expl'!$O$26,'Hypotheses expl'!$O$30,'Hypotheses expl'!$O$34,'Hypotheses expl'!$O$42,'Hypotheses expl'!$O$38,'Hypotheses expl'!$O$46,'Hypotheses expl'!$O$50,'Hypotheses expl'!$O$54,'Hypotheses expl'!$O$58,'Hypotheses expl'!$O$62,'Hypotheses expl'!$O$66)),0) -> 0 | G12: =IFERROR('Compte résultat prévi'!$C$156*(SUM('Hypotheses expl'!G10,'Hypotheses expl'!G14,'Hypotheses expl'!G18,'Hypotheses expl'!G22,'Hypotheses expl'!G26,'Hypotheses expl'!G30,'Hypotheses expl'!G34,'Hypotheses expl'!G42,'Hypotheses expl'!G38,'Hypotheses expl'!G46,'Hypotheses expl'!G50,'Hypotheses expl'!G54,'Hypotheses expl'!G58,'Hypotheses expl'!G62,'Hypotheses expl'!G66)/SUM('Hypotheses expl'!$O$10,'Hypotheses expl'!$O$14,'Hypotheses expl'!$O$18,'Hypotheses expl'!$O$22,'Hypotheses expl'!$O$26,'Hypotheses expl'!$O$30,'Hypotheses expl'!$O$34,'Hypotheses expl'!$O$42,'Hypotheses expl'!$O$38,'Hypotheses expl'!$O$46,'Hypotheses expl'!$O$50,'Hypotheses expl'!$O$54,'Hypotheses expl'!$O$58,'Hypotheses expl'!$O$62,'Hypotheses expl'!$O$66)),0) -> 0 | H12: =IFERROR('Compte résultat prévi'!$C$156*(SUM('Hypotheses expl'!H10,'Hypotheses expl'!H14,'Hypotheses expl'!H18,'Hypotheses expl'!H22,'Hypotheses expl'!H26,'Hypotheses expl'!H30,'Hypotheses expl'!H34,'Hypotheses expl'!H42,'Hypotheses expl'!H38,'Hypotheses expl'!H46,'Hypotheses expl'!H50,'Hypotheses expl'!H54,'Hypotheses expl'!H58,'Hypotheses expl'!H62,'Hypotheses expl'!H66)/SUM('Hypotheses expl'!$O$10,'Hypotheses expl'!$O$14,'Hypotheses expl'!$O$18,'Hypotheses expl'!$O$22,'Hypotheses expl'!$O$26,'Hypotheses expl'!$O$30,'Hypotheses expl'!$O$34,'Hypotheses expl'!$O$42,'Hypotheses expl'!$O$38,'Hypotheses expl'!$O$46,'Hypotheses expl'!$O$50,'Hypotheses expl'!$O$54,'Hypotheses expl'!$O$58,'Hypotheses expl'!$O$62,'Hypotheses expl'!$O$66)),0) -> 0 | I12: =IFERROR('Compte résultat prévi'!$C$156*(SUM('Hypotheses expl'!I10,'Hypotheses expl'!I14,'Hypotheses expl'!I18,'Hypotheses expl'!I22,'Hypotheses expl'!I26,'Hypotheses expl'!I30,'Hypotheses expl'!I34,'Hypotheses expl'!I42,'Hypotheses expl'!I38,'Hypotheses expl'!I46,'Hypotheses expl'!I50,'Hypotheses expl'!I54,'Hypotheses expl'!I58,'Hypotheses expl'!I62,'Hypotheses expl'!I66)/SUM('Hypotheses expl'!$O$10,'Hypotheses expl'!$O$14,'Hypotheses expl'!$O$18,'Hypotheses expl'!$O$22,'Hypotheses expl'!$O$26,'Hypotheses expl'!$O$30,'Hypotheses expl'!$O$34,'Hypotheses expl'!$O$42,'Hypotheses expl'!$O$38,'Hypotheses expl'!$O$46,'Hypotheses expl'!$O$50,'Hypotheses expl'!$O$54,'Hypotheses expl'!$O$58,'Hypotheses expl'!$O$62,'Hypotheses expl'!$O$66)),0) -> 0 | J12: =IFERROR('Compte résultat prévi'!$C$156*(SUM('Hypotheses expl'!J10,'Hypotheses expl'!J14,'Hypotheses expl'!J18,'Hypotheses expl'!J22,'Hypotheses expl'!J26,'Hypotheses expl'!J30,'Hypotheses expl'!J34,'Hypotheses expl'!J42,'Hypotheses expl'!J38,'Hypotheses expl'!J46,'Hypotheses expl'!J50,'Hypotheses expl'!J54,'Hypotheses expl'!J58,'Hypotheses expl'!J62,'Hypotheses expl'!J66)/SUM('Hypotheses expl'!$O$10,'Hypotheses expl'!$O$14,'Hypotheses expl'!$O$18,'Hypotheses expl'!$O$22,'Hypotheses expl'!$O$26,'Hypotheses expl'!$O$30,'Hypotheses expl'!$O$34,'Hypotheses expl'!$O$42,'Hypotheses expl'!$O$38,'Hypotheses expl'!$O$46,'Hypotheses expl'!$O$50,'Hypotheses expl'!$O$54,'Hypotheses expl'!$O$58,'Hypotheses expl'!$O$62,'Hypotheses expl'!$O$66)),0) -> 0 | ... N12: =IFERROR('Compte résultat prévi'!$C$156*(SUM('Hypotheses expl'!N10,'Hypotheses expl'!N14,'Hypotheses expl'!N18,'Hypotheses expl'!N22,'Hypotheses expl'!N26,'Hypotheses expl'!N30,'Hypotheses expl'!N34,'Hypotheses expl'!N42,'Hypotheses expl'!N38,'Hypotheses expl'!N46,'Hypotheses expl'!N50,'Hypotheses expl'!N54,'Hypotheses expl'!N58,'Hypotheses expl'!N62,'Hypotheses expl'!N66)/SUM('Hypotheses expl'!$O$10,'Hypotheses expl'!$O$14,'Hypotheses expl'!$O$18,'Hypotheses expl'!$O$22,'Hypotheses expl'!$O$26,'Hypotheses expl'!$O$30,'Hypotheses expl'!$O$34,'Hypotheses expl'!$O$42,'Hypotheses expl'!$O$38,'Hypotheses expl'!$O$46,'Hypotheses expl'!$O$50,'Hypotheses expl'!$O$54,'Hypotheses expl'!$O$58,'Hypotheses expl'!$O$62,'Hypotheses expl'!$O$66)),0) -> 0
A13: Autres

Sheet Hypotheses hors expl (2)
A1: Début du prévisionnel | B1: =DATE(YEAR('Hypotheses expl'!B1)+1,MONTH('Hypotheses expl'!B1),DAY('Hypotheses expl'!B1)) -> 45292
A2: HYPOTHESES HORS EXPLOITATION
C3: =B1 -> 45292 | D3: =DATE(YEAR(C3),MONTH(C3)+1,DAY(C3)) -> 45323 | E3: =DATE(YEAR(D3),MONTH(D3)+1,DAY(D3)) -> 45352 | F3: =DATE(YEAR(E3),MONTH(E3)+1,DAY(E3)) -> 45383 | G3: =DATE(YEAR(F3),MONTH(F3)+1,DAY(F3)) -> 45413 | H3: =DATE(YEAR(G3),MONTH(G3)+1,DAY(G3)) -> 45444 | I3: =DATE(YEAR(H3),MONTH(H3)+1,DAY(H3)) -> 45474 | J3: =DATE(YEAR(I3),MONTH(I3)+1,DAY(I3)) -> 45505 | K3: =DATE(YEAR(J3),MONTH(J3)+1,DAY(J3)) -> 45536 | ... N3: =DATE(YEAR(M3),MONTH(M3)+1,DAY(M3)) -> 45627
A4: Ressources
A5: Apport associatif
A6: Emprunt
A7: Autres
A9: Besoins
A10: Investissement
A11: Remboursement emprunt
A12: TVA due (fonctionnement courant) | C12: =IFERROR('Compte résultat prévi'!$I$156*(SUM('Hypotheses expl (3,)'!C10,'Hypotheses expl (3,)'!C14,'Hypotheses expl (3,)'!C18,'Hypotheses expl (3,)'!C22,'Hypotheses expl (3,)'!C26,'Hypotheses expl (3,)'!C30,'Hypotheses expl (3,)'!C34,'Hypotheses expl (3,)'!C42,'Hypotheses expl (3,)'!C38,'Hypotheses expl (3,)'!C46,'Hypotheses expl (3,)'!C50,'Hypotheses expl (3,)'!C54,'Hypotheses expl (3,)'!C58,'Hypotheses expl (3,)'!C62,'Hypotheses expl (3,)'!C66)/SUM('Hypotheses expl (3,)'!$O$10,'Hypotheses expl (3,)'!$O$14,'Hypotheses expl (3,)'!$O$18,'Hypotheses expl (3,)'!$O$22,'Hypotheses expl (3,)'!$O$26,'Hypotheses expl (3,)'!$O$30,'Hypotheses expl (3,)'!$O$34,'Hypotheses expl (3,)'!$O$42,'Hypotheses expl (3,)'!$O$38,'Hypotheses expl (3,)'!$O$46,'Hypotheses expl (3,)'!$O$50,'Hypotheses expl (3,)'!$O$54,'Hypotheses expl (3,)'!$O$58,'Hypotheses expl (3,)'!$O$62,'Hypotheses expl (3,)'!$O$66)),0) -> 0 | D12: =IFERROR('Compte résultat prévi'!$I$156*(SUM('Hypotheses expl (3,)'!D10,'Hypotheses expl (3,)'!D14,'Hypotheses expl (3,)'!D18,'Hypotheses expl (3,)'!D22,'Hypotheses expl (3,)'!D26,'Hypotheses expl (3,)'!D30,'Hypotheses expl (3,)'!D34,'Hypotheses expl (3,)'!D42,'Hypotheses expl (3,)'!D38,'Hypotheses expl (3,)'!D46,'Hypotheses expl (3,)'!D50,'Hypotheses expl (3,)'!D54,'Hypotheses expl (3,)'!D58,'Hypotheses expl (3,)'!D62,'Hypotheses expl (3,)'!D66)/SUM('Hypotheses expl (3,)'!$O$10,'Hypotheses expl (3,)'!$O$14,'Hypotheses expl (3,)'!$O$18,'Hypotheses expl (3,)'!$O$22,'Hypotheses expl (3,)'!$O$26,'Hypotheses expl (3,)'!$O$30,'Hypotheses expl (3,)'!$O$34,'Hypotheses expl (3,)'!$O$42,'Hypotheses expl (3,)'!$O$38,'Hypotheses expl (3,)'!$O$46,'Hypotheses expl (3,)'!$O$50,'Hypotheses expl (3,)'!$O$54,'Hypotheses expl (3,)'!$O$58,'Hypotheses expl (3,)'!$O$62,'Hypotheses expl (3,)'!$O$66)),0) -> 0 | E12: =IFERROR('Compte résultat prévi'!$I$156*(SUM('Hypotheses expl (3,)'!E10,'Hypotheses expl (3,)'!E14,'Hypotheses expl (3,)'!E18,'Hypotheses expl (3,)'!E22,'Hypotheses expl (3,)'!E26,'Hypotheses expl (3,)'!E30,'Hypotheses expl (3,)'!E34,'Hypotheses expl (3,)'!E42,'Hypotheses expl (3,)'!E38,'Hypotheses expl (3,)'!E46,'Hypotheses expl (3,)'!E50,'Hypotheses expl (3,)'!E54,'Hypotheses expl (3,)'!E58,'Hypotheses expl (3,)'!E62,'Hypotheses expl (3,)'!E66)/SUM('Hypotheses expl (3,)'!$O$10,'Hypotheses expl (3,)'!$O$14,'Hypotheses expl (3,)'!$O$18,'Hypotheses expl (3,)'!$O$22,'Hypotheses expl (3,)'!$O$26,'Hypotheses expl (3,)'!$O$30,'Hypotheses expl (3,)'!$O$34,'Hypotheses expl (3,)'!$O$42,'Hypotheses expl (3,)'!$O$38,'Hypotheses expl (3,)'!$O$46,'Hypotheses expl (3,)'!$O$50,'Hypotheses expl (3,)'!$O$54,'Hypotheses expl (3,)'!$O$58,'Hypotheses expl (3,)'!$O$62,'Hypotheses expl (3,)'!$O$66)),0) -> 0 | F12: =IFERROR('Compte résultat prévi'!$I$156*(SUM('Hypotheses expl (3,)'!F10,'Hypotheses expl (3,)'!F14,'Hypotheses expl (3,)'!F18,'Hypotheses expl (3,)'!F22,'Hypotheses expl (3,)'!F26,'Hypotheses expl (3,)'!F30,'Hypotheses expl (3,)'!F34,'Hypotheses expl (3,)'!F42,'Hypotheses expl (3,)'!F38,'Hypotheses expl (3,)'!F46,'Hypotheses expl (3,)'!F50,'Hypotheses expl (3,)'!F54,'Hypotheses expl (3,)'!F58,'Hypotheses expl (3,)'!F62,'Hypotheses expl (3,)'!F66)/SUM('Hypotheses expl (3,)'!$O$10,'Hypotheses expl (3,)'!$O$14,'Hypotheses expl (3,)'!$O$18,'Hypotheses expl (3,)'!$O$22,'Hypotheses expl (3,)'!$O$26,'Hypotheses expl (3,)'!$O$30,'Hypotheses expl (3,)'!$O$34,'Hypotheses expl (3,)'!$O$42,'Hypotheses expl (3,)'!$O$38,'Hypotheses expl (3,)'!$O$46,'Hypotheses expl (3,)'!$O$50,'Hypotheses expl (3,)'!$O$54,'Hypotheses expl (3,)'!$O$58,'Hypotheses expl (3,)'!$O$62,'Hypotheses expl (3,)'!$O$66)),0) -> 0 | G12: =IFERROR('Compte résultat prévi'!$I$156*(SUM('Hypotheses expl (3,)'!G10,'Hypotheses expl (3,)'!G14,'Hypotheses expl (3,)'!G18,'Hypotheses expl (3,)'!G22,'Hypotheses expl (3,)'!G26,'Hypotheses expl (3,)'!G30,'Hypotheses expl (3,)'!G34,'Hypotheses expl (3,)'!G42,'Hypotheses expl (3,)'!G38,'Hypotheses expl (3,)'!G46,'Hypotheses expl (3,)'!G50,'Hypotheses expl (3,)'!G54,'Hypotheses expl (3,)'!G58,'Hypotheses expl (3,)'!G62,'Hypotheses expl (3,)'!G66)/SUM('Hypotheses expl (3,)'!$O$10,'Hypotheses expl (3,)'!$O$14,'Hypotheses expl (3,)'!$O$18,'Hypotheses expl (3,)'!$O$22,'Hypotheses expl (3,)'!$O$26,'Hypotheses expl (3,)'!$O$30,'Hypotheses expl (3,)'!$O$34,'Hypotheses expl (3,)'!$O$42,'Hypotheses expl (3,)'!$O$38,'Hypotheses expl (3,)'!$O$46,'Hypotheses expl (3,)'!$O$50,'Hypotheses expl (3,)'!$O$54,'Hypotheses expl (3,)'!$O$58,'Hypotheses expl (3,)'!$O$62,'Hypotheses expl (3,)'!$O$66)),0) -> 0 | H12: =IFERROR('Compte résultat prévi'!$I$156*(SUM('Hypotheses expl (3,)'!H10,'Hypotheses expl (3,)'!H14,'Hypotheses expl (3,)'!H18,'Hypotheses expl (3,)'!H22,'Hypotheses expl (3,)'!H26,'Hypotheses expl (3,)'!H30,'Hypotheses expl (3,)'!H34,'Hypotheses expl (3,)'!H42,'Hypotheses expl (3,)'!H38,'Hypotheses expl (3,)'!H46,'Hypotheses expl (3,)'!H50,'Hypotheses expl (3,)'!H54,'Hypotheses expl (3,)'!H58,'Hypotheses expl (3,)'!H62,'Hypotheses expl (3,)'!H66)/SUM('Hypotheses expl (3,)'!$O$10,'Hypotheses expl (3,)'!$O$14,'Hypotheses expl (3,)'!$O$18,'Hypotheses expl (3,)'!$O$22,'Hypotheses expl (3,)'!$O$26,'Hypotheses expl (3,)'!$O$30,'Hypotheses expl (3,)'!$O$34,'Hypotheses expl (3,)'!$O$42,'Hypotheses expl (3,)'!$O$38,'Hypotheses expl (3,)'!$O$46,'Hypotheses expl (3,)'!$O$50,'Hypotheses expl (3,)'!$O$54,'Hypotheses expl (3,)'!$O$58,'Hypotheses expl (3,)'!$O$62,'Hypotheses expl (3,)'!$O$66)),0) -> 0 | I12: =IFERROR('Compte résultat prévi'!$I$156*(SUM('Hypotheses expl (3,)'!I10,'Hypotheses expl (3,)'!I14,'Hypotheses expl (3,)'!I18,'Hypotheses expl (3,)'!I22,'Hypotheses expl (3,)'!I26,'Hypotheses expl (3,)'!I30,'Hypotheses expl (3,)'!I34,'Hypotheses expl (3,)'!I42,'Hypotheses expl (3,)'!I38,'Hypotheses expl (3,)'!I46,'Hypotheses expl (3,)'!I50,'Hypotheses expl (3,)'!I54,'Hypotheses expl (3,)'!I58,'Hypotheses expl (3,)'!I62,'Hypotheses expl (3,)'!I66)/SUM('Hypotheses expl (3,)'!$O$10,'Hypotheses expl (3,)'!$O$14,'Hypotheses expl (3,)'!$O$18,'Hypotheses expl (3,)'!$O$22,'Hypotheses expl (3,)'!$O$26,'Hypotheses expl (3,)'!$O$30,'Hypotheses expl (3,)'!$O$34,'Hypotheses expl (3,)'!$O$42,'Hypotheses expl (3,)'!$O$38,'Hypotheses expl (3,)'!$O$46,'Hypotheses expl (3,)'!$O$50,'Hypotheses expl (3,)'!$O$54,'Hypotheses expl (3,)'!$O$58,'Hypotheses expl (3,)'!$O$62,'Hypotheses expl (3,)'!$O$66)),0) -> 0 | J12: =IFERROR('Compte résultat prévi'!$I$156*(SUM('Hypotheses expl (3,)'!J10,'Hypotheses expl (3,)'!J14,'Hypotheses expl (3,)'!J18,'Hypotheses expl (3,)'!J22,'Hypotheses expl (3,)'!J26,'Hypotheses expl (3,)'!J30,'Hypotheses expl (3,)'!J34,'Hypotheses expl (3,)'!J42,'Hypotheses expl (3,)'!J38,'Hypotheses expl (3,)'!J46,'Hypotheses expl (3,)'!J50,'Hypotheses expl (3,)'!J54,'Hypotheses expl (3,)'!J58,'Hypotheses expl (3,)'!J62,'Hypotheses expl (3,)'!J66)/SUM('Hypotheses expl (3,)'!$O$10,'Hypotheses expl (3,)'!$O$14,'Hypotheses expl (3,)'!$O$18,'Hypotheses expl (3,)'!$O$22,'Hypotheses expl (3,)'!$O$26,'Hypotheses expl (3,)'!$O$30,'Hypotheses expl (3,)'!$O$34,'Hypotheses expl (3,)'!$O$42,'Hypotheses expl (3,)'!$O$38,'Hypotheses expl (3,)'!$O$46,'Hypotheses expl (3,)'!$O$50,'Hypotheses expl (3,)'!$O$54,'Hypotheses expl (3,)'!$O$58,'Hypotheses expl (3,)'!$O$62,'Hypotheses expl (3,)'!$O$66)),0) -> 0 | ... N12: =IFERROR('Compte résultat prévi'!$I$156*(SUM('Hypotheses expl (3,)'!N10,'Hypotheses expl (3,)'!N14,'Hypotheses expl (3,)'!N18,'Hypotheses expl (3,)'!N22,'Hypotheses expl (3,)'!N26,'Hypotheses expl (3,)'!N30,'Hypotheses expl (3,)'!N34,'Hypotheses expl (3,)'!N42,'Hypotheses expl (3,)'!N38,'Hypotheses expl (3,)'!N46,'Hypotheses expl (3,)'!N50,'Hypotheses expl (3,)'!N54,'Hypotheses expl (3,)'!N58,'Hypotheses expl (3,)'!N62,'Hypotheses expl (3,)'!N66)/SUM('Hypotheses expl (3,)'!$O$10,'Hypotheses expl (3,)'!$O$14,'Hypotheses expl (3,)'!$O$18,'Hypotheses expl (3,)'!$O$22,'Hypotheses expl (3,)'!$O$26,'Hypotheses expl (3,)'!$O$30,'Hypotheses expl (3,)'!$O$34,'Hypotheses expl (3,)'!$O$42,'Hypotheses expl (3,)'!$O$38,'Hypotheses expl (3,)'!$O$46,'Hypotheses expl (3,)'!$O$50,'Hypotheses expl (3,)'!$O$54,'Hypotheses expl (3,)'!$O$58,'Hypotheses expl (3,)'!$O$62,'Hypotheses expl (3,)'!$O$66)),0) -> 0
A13: Autres

Sheet Hypotheses hors expl (3)
A1: Début du prévisionnel | B1: =DATE(YEAR('Hypotheses expl'!B1)+2,MONTH('Hypotheses expl'!B1),DAY('Hypotheses expl'!B1)) -> 45658
A2: HYPOTHESES HORS EXPLOITATION
C3: =B1 -> 45658 | D3: =DATE(YEAR(C3),MONTH(C3)+1,DAY(C3)) -> 45689 | E3: =DATE(YEAR(D3),MONTH(D3)+1,DAY(D3)) -> 45717 | F3: =DATE(YEAR(E3),MONTH(E3)+1,DAY(E3)) -> 45748 | G3: =DATE(YEAR(F3),MONTH(F3)+1,DAY(F3)) -> 45778 | H3: =DATE(YEAR(G3),MONTH(G3)+1,DAY(G3)) -> 45809 | I3: =DATE(YEAR(H3),MONTH(H3)+1,DAY(H3)) -> 45839 | J3: =DATE(YEAR(I3),MONTH(I3)+1,DAY(I3)) -> 45870 | K3: =DATE(YEAR(J3),MONTH(J3)+1,DAY(J3)) -> 45901 | ... N3: =DATE(YEAR(M3),MONTH(M3)+1,DAY(M3)) -> 45992
A4: Ressources
A5: Apport associatif
A6: Emprunt
A7: Autres
A9: Besoins
A10: Investissement
A11: Remboursement emprunt
A12: TVA due (fonctionnement courant) | C12: =IFERROR('Compte résultat prévi'!$O$156*(SUM('Hypotheses expl (2)'!C10,'Hypotheses expl (2)'!C14,'Hypotheses expl (2)'!C18,'Hypotheses expl (2)'!C22,'Hypotheses expl (2)'!C26,'Hypotheses expl (2)'!C30,'Hypotheses expl (2)'!C34,'Hypotheses expl (2)'!C42,'Hypotheses expl (2)'!C38,'Hypotheses expl (2)'!C46,'Hypotheses expl (2)'!C50,'Hypotheses expl (2)'!C54,'Hypotheses expl (2)'!C58,'Hypotheses expl (2)'!C62,'Hypotheses expl (2)'!C66)/SUM('Hypotheses expl (2)'!$O$10,'Hypotheses expl (2)'!$O$14,'Hypotheses expl (2)'!$O$18,'Hypotheses expl (2)'!$O$22,'Hypotheses expl (2)'!$O$26,'Hypotheses expl (2)'!$O$30,'Hypotheses expl (2)'!$O$34,'Hypotheses expl (2)'!$O$42,'Hypotheses expl (2)'!$O$38,'Hypotheses expl (2)'!$O$46,'Hypotheses expl (2)'!$O$50,'Hypotheses expl (2)'!$O$54,'Hypotheses expl (2)'!$O$58,'Hypotheses expl (2)'!$O$62,'Hypotheses expl (2)'!$O$66)),0) -> 0 | D12: =IFERROR('Compte résultat prévi'!$O$156*(SUM('Hypotheses expl (2)'!D10,'Hypotheses expl (2)'!D14,'Hypotheses expl (2)'!D18,'Hypotheses expl (2)'!D22,'Hypotheses expl (2)'!D26,'Hypotheses expl (2)'!D30,'Hypotheses expl (2)'!D34,'Hypotheses expl (2)'!D42,'Hypotheses expl (2)'!D38,'Hypotheses expl (2)'!D46,'Hypotheses expl (2)'!D50,'Hypotheses expl (2)'!D54,'Hypotheses expl (2)'!D58,'Hypotheses expl (2)'!D62,'Hypotheses expl (2)'!D66)/SUM('Hypotheses expl (2)'!$O$10,'Hypotheses expl (2)'!$O$14,'Hypotheses expl (2)'!$O$18,'Hypotheses expl (2)'!$O$22,'Hypotheses expl (2)'!$O$26,'Hypotheses expl (2)'!$O$30,'Hypotheses expl (2)'!$O$34,'Hypotheses expl (2)'!$O$42,'Hypotheses expl (2)'!$O$38,'Hypotheses expl (2)'!$O$46,'Hypotheses expl (2)'!$O$50,'Hypotheses expl (2)'!$O$54,'Hypotheses expl (2)'!$O$58,'Hypotheses expl (2)'!$O$62,'Hypotheses expl (2)'!$O$66)),0) -> 0 | E12: =IFERROR('Compte résultat prévi'!$O$156*(SUM('Hypotheses expl (2)'!E10,'Hypotheses expl (2)'!E14,'Hypotheses expl (2)'!E18,'Hypotheses expl (2)'!E22,'Hypotheses expl (2)'!E26,'Hypotheses expl (2)'!E30,'Hypotheses expl (2)'!E34,'Hypotheses expl (2)'!E42,'Hypotheses expl (2)'!E38,'Hypotheses expl (2)'!E46,'Hypotheses expl (2)'!E50,'Hypotheses expl (2)'!E54,'Hypotheses expl (2)'!E58,'Hypotheses expl (2)'!E62,'Hypotheses expl (2)'!E66)/SUM('Hypotheses expl (2)'!$O$10,'Hypotheses expl (2)'!$O$14,'Hypotheses expl (2)'!$O$18,'Hypotheses expl (2)'!$O$22,'Hypotheses expl (2)'!$O$26,'Hypotheses expl (2)'!$O$30,'Hypotheses expl (2)'!$O$34,'Hypotheses expl (2)'!$O$42,'Hypotheses expl (2)'!$O$38,'Hypotheses expl (2)'!$O$46,'Hypotheses expl (2)'!$O$50,'Hypotheses expl (2)'!$O$54,'Hypotheses expl (2)'!$O$58,'Hypotheses expl (2)'!$O$62,'Hypotheses expl (2)'!$O$66)),0) -> 0 | F12: =IFERROR('Compte résultat prévi'!$O$156*(SUM('Hypotheses expl (2)'!F10,'Hypotheses expl (2)'!F14,'Hypotheses expl (2)'!F18,'Hypotheses expl (2)'!F22,'Hypotheses expl (2)'!F26,'Hypotheses expl (2)'!F30,'Hypotheses expl (2)'!F34,'Hypotheses expl (2)'!F42,'Hypotheses expl (2)'!F38,'Hypotheses expl (2)'!F46,'Hypotheses expl (2)'!F50,'Hypotheses expl (2)'!F54,'Hypotheses expl (2)'!F58,'Hypotheses expl (2)'!F62,'Hypotheses expl (2)'!F66)/SUM('Hypotheses expl (2)'!$O$10,'Hypotheses expl (2)'!$O$14,'Hypotheses expl (2)'!$O$18,'Hypotheses expl (2)'!$O$22,'Hypotheses expl (2)'!$O$26,'Hypotheses expl (2)'!$O$30,'Hypotheses expl (2)'!$O$34,'Hypotheses expl (2)'!$O$42,'Hypotheses expl (2)'!$O$38,'Hypotheses expl (2)'!$O$46,'Hypotheses expl (2)'!$O$50,'Hypotheses expl (2)'!$O$54,'Hypotheses expl (2)'!$O$58,'Hypotheses expl (2)'!$O$62,'Hypotheses expl (2)'!$O$66)),0) -> 0 | G12: =IFERROR('Compte résultat prévi'!$O$156*(SUM('Hypotheses expl (2)'!G10,'Hypotheses expl (2)'!G14,'Hypotheses expl (2)'!G18,'Hypotheses expl (2)'!G22,'Hypotheses expl (2)'!G26,'Hypotheses expl (2)'!G30,'Hypotheses expl (2)'!G34,'Hypotheses expl (2)'!G42,'Hypotheses expl (2)'!G38,'Hypotheses expl (2)'!G46,'Hypotheses expl (2)'!G50,'Hypotheses expl (2)'!G54,'Hypotheses expl (2)'!G58,'Hypotheses expl (2)'!G62,'Hypotheses expl (2)'!G66)/SUM('Hypotheses expl (2)'!$O$10,'Hypotheses expl (2)'!$O$14,'Hypotheses expl (2)'!$O$18,'Hypotheses expl (2)'!$O$22,'Hypotheses expl (2)'!$O$26,'Hypotheses expl (2)'!$O$30,'Hypotheses expl (2)'!$O$34,'Hypotheses expl (2)'!$O$42,'Hypotheses expl (2)'!$O$38,'Hypotheses expl (2)'!$O$46,'Hypotheses expl (2)'!$O$50,'Hypotheses expl (2)'!$O$54,'Hypotheses expl (2)'!$O$58,'Hypotheses expl (2)'!$O$62,'Hypotheses expl (2)'!$O$66)),0) -> 0 | H12: =IFERROR('Compte résultat prévi'!$O$156*(SUM('Hypotheses expl (2)'!H10,'Hypotheses expl (2)'!H14,'Hypotheses expl (2)'!H18,'Hypotheses expl (2)'!H22,'Hypotheses expl (2)'!H26,'Hypotheses expl (2)'!H30,'Hypotheses expl (2)'!H34,'Hypotheses expl (2)'!H42,'Hypotheses expl (2)'!H38,'Hypotheses expl (2)'!H46,'Hypotheses expl (2)'!H50,'Hypotheses expl (2)'!H54,'Hypotheses expl (2)'!H58,'Hypotheses expl (2)'!H62,'Hypotheses expl (2)'!H66)/SUM('Hypotheses expl (2)'!$O$10,'Hypotheses expl (2)'!$O$14,'Hypotheses expl (2)'!$O$18,'Hypotheses expl (2)'!$O$22,'Hypotheses expl (2)'!$O$26,'Hypotheses expl (2)'!$O$30,'Hypotheses expl (2)'!$O$34,'Hypotheses expl (2)'!$O$42,'Hypotheses expl (2)'!$O$38,'Hypotheses expl (2)'!$O$46,'Hypotheses expl (2)'!$O$50,'Hypotheses expl (2)'!$O$54,'Hypotheses expl (2)'!$O$58,'Hypotheses expl (2)'!$O$62,'Hypotheses expl (2)'!$O$66)),0) -> 0 | I12: =IFERROR('Compte résultat prévi'!$O$156*(SUM('Hypotheses expl (2)'!I10,'Hypotheses expl (2)'!I14,'Hypotheses expl (2)'!I18,'Hypotheses expl (2)'!I22,'Hypotheses expl (2)'!I26,'Hypotheses expl (2)'!I30,'Hypotheses expl (2)'!I34,'Hypotheses expl (2)'!I42,'Hypotheses expl (2)'!I38,'Hypotheses expl (2)'!I46,'Hypotheses expl (2)'!I50,'Hypotheses expl (2)'!I54,'Hypotheses expl (2)'!I58,'Hypotheses expl (2)'!I62,'Hypotheses expl (2)'!I66)/SUM('Hypotheses expl (2)'!$O$10,'Hypotheses expl (2)'!$O$14,'Hypotheses expl (2)'!$O$18,'Hypotheses expl (2)'!$O$22,'Hypotheses expl (2)'!$O$26,'Hypotheses expl (2)'!$O$30,'Hypotheses expl (2)'!$O$34,'Hypotheses expl (2)'!$O$42,'Hypotheses expl (2)'!$O$38,'Hypotheses expl (2)'!$O$46,'Hypotheses expl (2)'!$O$50,'Hypotheses expl (2)'!$O$54,'Hypotheses expl (2)'!$O$58,'Hypotheses expl (2)'!$O$62,'Hypotheses expl (2)'!$O$66)),0) -> 0 | J12: =IFERROR('Compte résultat prévi'!$O$156*(SUM('Hypotheses expl (2)'!J10,'Hypotheses expl (2)'!J14,'Hypotheses expl (2)'!J18,'Hypotheses expl (2)'!J22,'Hypotheses expl (2)'!J26,'Hypotheses expl (2)'!J30,'Hypotheses expl (2)'!J34,'Hypotheses expl (2)'!J42,'Hypotheses expl (2)'!J38,'Hypotheses expl (2)'!J46,'Hypotheses expl (2)'!J50,'Hypotheses expl (2)'!J54,'Hypotheses expl (2)'!J58,'Hypotheses expl (2)'!J62,'Hypotheses expl (2)'!J66)/SUM('Hypotheses expl (2)'!$O$10,'Hypotheses expl (2)'!$O$14,'Hypotheses expl (2)'!$O$18,'Hypotheses expl (2)'!$O$22,'Hypotheses expl (2)'!$O$26,'Hypotheses expl (2)'!$O$30,'Hypotheses expl (2)'!$O$34,'Hypotheses expl (2)'!$O$42,'Hypotheses expl (2)'!$O$38,'Hypotheses expl (2)'!$O$46,'Hypotheses expl (2)'!$O$50,'Hypotheses expl (2)'!$O$54,'Hypotheses expl (2)'!$O$58,'Hypotheses expl (2)'!$O$62,'Hypotheses expl (2)'!$O$66)),0) -> 0 | ... N12: =IFERROR('Compte résultat prévi'!$O$156*(SUM('Hypotheses expl (2)'!N10,'Hypotheses expl (2)'!N14,'Hypotheses expl (2)'!N18,'Hypotheses expl (2)'!N22,'Hypotheses expl (2)'!N26,'Hypotheses expl (2)'!N30,'Hypotheses expl (2)'!N34,'Hypotheses expl (2)'!N42,'Hypotheses expl (2)'!N38,'Hypotheses expl (2)'!N46,'Hypotheses expl (2)'!N50,'Hypotheses expl (2)'!N54,'Hypotheses expl (2)'!N58,'Hypotheses expl (2)'!N62,'Hypotheses expl (2)'!N66)/SUM('Hypotheses expl (2)'!$O$10,'Hypotheses expl (2)'!$O$14,'Hypotheses expl (2)'!$O$18,'Hypotheses expl (2)'!$O$22,'Hypotheses expl (2)'!$O$26,'Hypotheses expl (2)'!$O$30,'Hypotheses expl (2)'!$O$34,'Hypotheses expl (2)'!$O$42,'Hypotheses expl (2)'!$O$38,'Hypotheses expl (2)'!$O$46,'Hypotheses expl (2)'!$O$50,'Hypotheses expl (2)'!$O$54,'Hypotheses expl (2)'!$O$58,'Hypotheses expl (2)'!$O$62,'Hypotheses expl (2)'!$O$66)),0) -> 0
A13: Autres

Sheet Compte résultat prévi
A1: BUDGET PREVISIONNEL ANALYTIQUE (hors fisca)
A3: LIBELLE PREVISIONNEL BUDGETAIRE | B3: Clé | C3: =DATE(YEAR('Hypotheses expl'!B1),12,31) -> 45291 | I3: =DATE(YEAR('Hypotheses expl'!B1)+1,12,31) -> 45657 | O3: =DATE(YEAR('Hypotheses expl'!B1)+2,12,31) -> 46022 | U3: =DATE(YEAR(C3)+3,MONTH(C3),DAY(C3)) -> 46387 | V3: =DATE(YEAR(U3)+1,MONTH(U3),DAY(U3)) -> 46752
